/Users/emilywesel/opt/anaconda3/lib/python3.8/site-packages/pytorch_lightning/loggers/wandb.py:396: UserWarning: There is a wandb run already in progress and newly created instances of `WandbLogger` will reuse this run. If this is not desired, call `wandb.finish()` before instantiating `WandbLogger`.
  rank_zero_warn(
Global seed set to 23
GPU available: False, used: False
TPU available: False, using: 0 TPU cores
IPU available: False, using: 0 IPUs
HPU available: False, using: 0 HPUs
   | Name                 | Type               | Params
-------------------------------------------------------------
0  | resnet               | ResNet             | 14.4 M
1  | fc1                  | Linear             | 16.4 K
2  | fc2                  | Linear             | 16.4 K
3  | fc3                  | Linear             | 16.5 K
4  | fc4                  | Linear             | 16.4 K
5  | fc5                  | Linear             | 65
6  | center_loss          | CenterLoss         | 128
7  | bce_loss             | BCEWithLogitsLoss  | 0
8  | triplet_loss         | TripletMarginLoss  | 0
9  | train_macro_accuracy | MulticlassAccuracy | 0
10 | val_macro_accuracy   | MulticlassAccuracy | 0
11 | test_macro_accuracy  | MulticlassAccuracy | 0
12 | train_accuracy       | MulticlassAccuracy | 0
13 | val_accuracy         | MulticlassAccuracy | 0
14 | test_accuracy        | MulticlassAccuracy | 0
-------------------------------------------------------------
14.5 M    Trainable params
0         Non-trainable params
14.5 M    Total params
57.950    Total estimated model params size (MB)
/Users/emilywesel/opt/anaconda3/lib/python3.8/site-packages/pytorch_lightning/trainer/connectors/data_connector.py:224: PossibleUserWarning: The dataloader, val_dataloader 0, does not have many workers which may be a bottleneck. Consider increasing the value of the `num_workers` argument` (try 8 which is the number of cpus on this machine) in the `DataLoader` init to improve performance.
  rank_zero_warn(
Train dataset length: 424
Validation dataset length: 142
Sanity Checking: 0it [00:00, ?it/s]
Traceback (most recent call last):
  File "main.py", line 225, in <module>
    main_triplet(wandb, wandb_logger)
  File "main.py", line 191, in main_triplet
    trainer.fit(model=model, train_dataloaders=train_loader, val_dataloaders=val_loader)
  File "/Users/emilywesel/opt/anaconda3/lib/python3.8/site-packages/pytorch_lightning/trainer/trainer.py", line 603, in fit
    call._call_and_handle_interrupt(
  File "/Users/emilywesel/opt/anaconda3/lib/python3.8/site-packages/pytorch_lightning/trainer/call.py", line 38, in _call_and_handle_interrupt
    return trainer_fn(*args, **kwargs)
  File "/Users/emilywesel/opt/anaconda3/lib/python3.8/site-packages/pytorch_lightning/trainer/trainer.py", line 645, in _fit_impl
    self._run(model, ckpt_path=self.ckpt_path)
  File "/Users/emilywesel/opt/anaconda3/lib/python3.8/site-packages/pytorch_lightning/trainer/trainer.py", line 1098, in _run
    results = self._run_stage()
  File "/Users/emilywesel/opt/anaconda3/lib/python3.8/site-packages/pytorch_lightning/trainer/trainer.py", line 1177, in _run_stage
    self._run_train()
  File "/Users/emilywesel/opt/anaconda3/lib/python3.8/site-packages/pytorch_lightning/trainer/trainer.py", line 1190, in _run_train
    self._run_sanity_check()
  File "/Users/emilywesel/opt/anaconda3/lib/python3.8/site-packages/pytorch_lightning/trainer/trainer.py", line 1262, in _run_sanity_check
    val_loop.run()
  File "/Users/emilywesel/opt/anaconda3/lib/python3.8/site-packages/pytorch_lightning/loops/loop.py", line 199, in run
    self.advance(*args, **kwargs)
  File "/Users/emilywesel/opt/anaconda3/lib/python3.8/site-packages/pytorch_lightning/loops/dataloader/evaluation_loop.py", line 152, in advance
    dl_outputs = self.epoch_loop.run(self._data_fetcher, dl_max_batches, kwargs)
  File "/Users/emilywesel/opt/anaconda3/lib/python3.8/site-packages/pytorch_lightning/loops/loop.py", line 199, in run
    self.advance(*args, **kwargs)
  File "/Users/emilywesel/opt/anaconda3/lib/python3.8/site-packages/pytorch_lightning/loops/epoch/evaluation_epoch_loop.py", line 121, in advance
    batch = next(data_fetcher)
  File "/Users/emilywesel/opt/anaconda3/lib/python3.8/site-packages/pytorch_lightning/utilities/fetching.py", line 184, in __next__
    return self.fetching_function()
  File "/Users/emilywesel/opt/anaconda3/lib/python3.8/site-packages/pytorch_lightning/utilities/fetching.py", line 265, in fetching_function
    self._fetch_next_batch(self.dataloader_iter)
  File "/Users/emilywesel/opt/anaconda3/lib/python3.8/site-packages/pytorch_lightning/utilities/fetching.py", line 280, in _fetch_next_batch
    batch = next(iterator)
  File "/Users/emilywesel/opt/anaconda3/lib/python3.8/site-packages/torch/utils/data/dataloader.py", line 628, in __next__
    data = self._next_data()
  File "/Users/emilywesel/opt/anaconda3/lib/python3.8/site-packages/torch/utils/data/dataloader.py", line 1333, in _next_data
    return self._process_data(data)
  File "/Users/emilywesel/opt/anaconda3/lib/python3.8/site-packages/torch/utils/data/dataloader.py", line 1359, in _process_data
    data.reraise()
  File "/Users/emilywesel/opt/anaconda3/lib/python3.8/site-packages/torch/_utils.py", line 543, in reraise
    raise exception
FileNotFoundError: Caught FileNotFoundError in DataLoader worker process 0.
Original Traceback (most recent call last):
  File "/Users/emilywesel/opt/anaconda3/lib/python3.8/site-packages/nibabel/loadsave.py", line 90, in load
    stat_result = os.stat(filename)
FileNotFoundError: [Errno 2] No such file or directory: '/scratch/users/ewesel/ncanda-multi-modal/T1/NCANDA_S00034.nii.gz'
During handling of the above exception, another exception occurred:
Traceback (most recent call last):
  File "/Users/emilywesel/opt/anaconda3/lib/python3.8/site-packages/torch/utils/data/_utils/worker.py", line 302, in _worker_loop
    data = fetcher.fetch(index)
  File "/Users/emilywesel/opt/anaconda3/lib/python3.8/site-packages/torch/utils/data/_utils/fetch.py", line 58, in fetch
    data = [self.dataset[idx] for idx in possibly_batched_index]
  File "/Users/emilywesel/opt/anaconda3/lib/python3.8/site-packages/torch/utils/data/_utils/fetch.py", line 58, in <listcomp>
    data = [self.dataset[idx] for idx in possibly_batched_index]
  File "/Users/emilywesel/Documents/GitHub/NCANDA_Contrastive/multimodal_dataset_triplet.py", line 113, in __getitem__
    image, tab, label = self.get_sample(subject_id)
  File "/Users/emilywesel/Documents/GitHub/NCANDA_Contrastive/multimodal_dataset_triplet.py", line 85, in get_sample
    image = nib.load(image_path)
  File "/Users/emilywesel/opt/anaconda3/lib/python3.8/site-packages/nibabel/loadsave.py", line 92, in load
    raise FileNotFoundError(f"No such file or no access: '{filename}'")
FileNotFoundError: No such file or no access: '/scratch/users/ewesel/ncanda-multi-modal/T1/NCANDA_S00034.nii.gz'